<?xml version="1.0"?>
<robot name="simple_biped">
    <link name="torso">
        <visual>
            <geometry>
                <box size="0.2 0.2 0.4"/>
            </geometry>
        </visual>
        <collision>
            <geometry>
                <box size="0.2 0.2 0.4"/>
            </geometry>
        </collision>
        <inertial>
            <mass value="6.0"/>
            <!-- Inertia for box: ixx/iyy = m*(d^2 + h^2)/12, izz = m*(w^2 + d^2)/12 -->
            <inertia
                ixx="0.0867" ixy="0" ixz="0"
                iyy="0.0867" iyz="0"
                izz="0.0400"/>
        </inertial>
    </link>

    <link name="left_leg">
        <visual>
            <geometry>
                <box size="0.1 0.1 0.4"/>
            </geometry>
        </visual>
        <collision>
            <geometry>
                <box size="0.1 0.1 0.4"/>
            </geometry>
        </collision>
        <inertial>
            <mass value="1.5"/>
            <!-- Inertia for box: ixx/iyy = m*(d^2 + h^2)/12, izz = m*(w^2 + d^2)/12 -->
            <inertia
                ixx="0.0427" ixy="0" ixz="0"
                iyy="0.0427" iyz="0"
                izz="0.0017"/>
        </inertial>
    </link>

    <link name="left_foot">
        <visual>
            <geometry>
                <box size="0.15 0.15 0.05"/>
            </geometry>
        </visual>
        <collision>
            <geometry>
                <box size="0.15 0.15 0.05"/>
            </geometry>
            <contact>
                <lateral_friction value="1.0"/>
                <rolling_friction value="0.1"/>
                <spinning_friction value="0.1"/>
                <restitution value="0.1"/>
            </contact>
        </collision>
        <inertial>
            <mass value="0.5"/>
            <inertia
                ixx="0.001" ixy="0" ixz="0"
                iyy="0.001" iyz="0"
                izz="0.001"/>
        </inertial>
    </link>

    <joint name="left_hip" type="revolute">
        <parent link="torso"/>
        <child link="left_leg"/>
        <origin xyz="-0.1 0 -0.2"/>
        <axis xyz="0 1 0"/>
        <limit lower="-0.7" upper="0.7" effort="1000" velocity="2.0"/>
        <dynamics damping="1.0" friction="0.5"/>
    </joint>

    <joint name="left_ankle" type="fixed">
        <parent link="left_leg"/>
        <child link="left_foot"/>
        <origin xyz="0 0 -0.225"/>
    </joint>

    <link name="right_leg">
        <visual>
            <geometry>
                <box size="0.1 0.1 0.4"/>
            </geometry>
        </visual>
        <collision>
            <geometry>
                <box size="0.1 0.1 0.4"/>
            </geometry>
        </collision>
        <inertial>
            <mass value="1.5"/>
            <!-- Inertia for box: ixx/iyy = m*(d^2 + h^2)/12, izz = m*(w^2 + d^2)/12 -->
            <inertia
                ixx="0.0427" ixy="0" ixz="0"
                iyy="0.0427" iyz="0"
                izz="0.0017"/>
        </inertial>
    </link>

    <link name="right_foot">
        <visual>
            <geometry>
                <box size="0.15 0.15 0.05"/>
            </geometry>
        </visual>
        <collision>
            <geometry>
                <box size="0.15 0.15 0.05"/>
            </geometry>
            <contact>
                <lateral_friction value="1.0"/>
                <rolling_friction value="0.1"/>
                <spinning_friction value="0.1"/>
                <restitution value="0.1"/>
            </contact>
        </collision>
        <inertial>
            <mass value="0.5"/>
            <inertia
                ixx="0.001" ixy="0" ixz="0"
                iyy="0.001" iyz="0"
                izz="0.001"/>
        </inertial>
    </link>

    <joint name="right_hip" type="revolute">
        <parent link="torso"/>
        <child link="right_leg"/>
        <origin xyz="0.1 0 -0.2"/>
        <axis xyz="0 1 0"/>
        <limit lower="-0.7" upper="0.7" effort="1000" velocity="2.0"/>
        <dynamics damping="1.0" friction="0.5"/>
    </joint>

    <joint name="right_ankle" type="fixed">
        <parent link="right_leg"/>
        <child link="right_foot"/>
        <origin xyz="0 0 -0.225"/>
    </joint>
</robot>
