<?xml version="1.0"?>
<robot name="simple_biped">
    <!-- Base link (torso) with lowered center of mass -->
    <link name="torso">
        <inertial>
            <origin xyz="0 0 -0.1" rpy="0 0 0"/>
            <mass value="10.0"/>
            <inertia ixx="0.1" ixy="0" ixz="0" iyy="0.1" iyz="0" izz="0.1"/>
        </inertial>
        <visual>
            <origin xyz="0 0 0" rpy="0 0 0"/>
            <geometry>
                <box size="0.2 0.1 0.4"/>
            </geometry>
            <material name="blue">
                <color rgba="0 0 1 1"/>
            </material>
        </visual>
        <collision>
            <origin xyz="0 0 0" rpy="0 0 0"/>
            <geometry>
                <box size="0.2 0.1 0.4"/>
            </geometry>
        </collision>
    </link>

    <!-- Left hip joint with improved damping -->
    <joint name="left_hip" type="revolute">
        <parent link="torso"/>
        <child link="left_upper_leg"/>
        <origin xyz="-0.15 0 -0.15" rpy="0 0 0"/>
        <axis xyz="0 1 0"/>
        <limit lower="-0.4" upper="0.4" effort="1000" velocity="1.0"/>
        <dynamics damping="2.0" friction="1.0"/>
    </joint>

    <!-- Left upper leg -->
    <link name="left_upper_leg">
        <inertial>
            <origin xyz="0 0 -0.2" rpy="0 0 0"/>
            <mass value="5.0"/>
            <inertia ixx="0.1" ixy="0" ixz="0" iyy="0.1" iyz="0" izz="0.1"/>
        </inertial>
        <visual>
            <origin xyz="0 0 -0.2" rpy="0 0 0"/>
            <geometry>
                <box size="0.1 0.1 0.4"/>
            </geometry>
            <material name="red">
                <color rgba="1 0 0 1"/>
            </material>
        </visual>
        <collision>
            <origin xyz="0 0 -0.2" rpy="0 0 0"/>
            <geometry>
                <box size="0.06 0.06 0.36"/>
            </geometry>
        </collision>
    </link>

    <!-- Left knee joint -->
    <joint name="left_knee" type="revolute">
        <parent link="left_upper_leg"/>
        <child link="left_lower_leg"/>
        <origin xyz="0 0 -0.4" rpy="0 0 0"/>
        <axis xyz="0 1 0"/>
        <limit lower="-0.4" upper="0.4" effort="1000" velocity="1.0"/>
        <dynamics damping="2.0" friction="1.0"/>
    </joint>

    <!-- Left lower leg -->
    <link name="left_lower_leg">
        <inertial>
            <origin xyz="0 0 -0.2" rpy="0 0 0"/>
            <mass value="3.0"/>
            <inertia ixx="0.1" ixy="0" ixz="0" iyy="0.1" iyz="0" izz="0.1"/>
        </inertial>
        <visual>
            <origin xyz="0 0 -0.2" rpy="0 0 0"/>
            <geometry>
                <box size="0.1 0.1 0.4"/>
            </geometry>
            <material name="green">
                <color rgba="0 1 0 1"/>
            </material>
        </visual>
        <collision>
            <origin xyz="0 0 -0.2" rpy="0 0 0"/>
            <geometry>
                <box size="0.06 0.06 0.36"/>
            </geometry>
        </collision>
    </link>

    <!-- Left foot with wider base and increased friction -->
    <joint name="left_ankle" type="fixed">
        <parent link="left_lower_leg"/>
        <child link="left_foot"/>
        <origin xyz="0 0 -0.4" rpy="0 0 0"/>
    </joint>

    <link name="left_foot">
        <inertial>
            <origin xyz="0 0 -0.025" rpy="0 0 0"/>
            <mass value="2.0"/>
            <inertia ixx="0.01" ixy="0" ixz="0" iyy="0.01" iyz="0" izz="0.01"/>
        </inertial>
        <visual>
            <origin xyz="0 0 -0.025" rpy="0 0 0"/>
            <geometry>
                <box size="0.2 0.2 0.05"/>
            </geometry>
            <material name="yellow">
                <color rgba="1 1 0 1"/>
            </material>
        </visual>
        <collision>
            <origin xyz="0 0 -0.025" rpy="0 0 0"/>
            <geometry>
                <box size="0.2 0.2 0.05"/>
            </geometry>
        </collision>
        <contact>
            <lateral_friction value="2.0"/>
            <rolling_friction value="0.2"/>
            <spinning_friction value="0.2"/>
            <restitution value="0.05"/>
        </contact>
    </link>

    <!-- Right hip joint with improved damping -->
    <joint name="right_hip" type="revolute">
        <parent link="torso"/>
        <child link="right_upper_leg"/>
        <origin xyz="0.15 0 -0.15" rpy="0 0 0"/>
        <axis xyz="0 1 0"/>
        <limit lower="-0.4" upper="0.4" effort="1000" velocity="1.0"/>
        <dynamics damping="2.0" friction="1.0"/>
    </joint>

    <!-- Right upper leg -->
    <link name="right_upper_leg">
        <inertial>
            <origin xyz="0 0 -0.2" rpy="0 0 0"/>
            <mass value="5.0"/>
            <inertia ixx="0.1" ixy="0" ixz="0" iyy="0.1" iyz="0" izz="0.1"/>
        </inertial>
        <visual>
            <origin xyz="0 0 -0.2" rpy="0 0 0"/>
            <geometry>
                <box size="0.1 0.1 0.4"/>
            </geometry>
            <material name="red">
                <color rgba="1 0 0 1"/>
            </material>
        </visual>
        <collision>
            <origin xyz="0 0 -0.2" rpy="0 0 0"/>
            <geometry>
                <box size="0.06 0.06 0.36"/>
            </geometry>
        </collision>
    </link>

    <!-- Right knee joint -->
    <joint name="right_knee" type="revolute">
        <parent link="right_upper_leg"/>
        <child link="right_lower_leg"/>
        <origin xyz="0 0 -0.4" rpy="0 0 0"/>
        <axis xyz="0 1 0"/>
        <limit lower="-0.4" upper="0.4" effort="1000" velocity="1.0"/>
        <dynamics damping="2.0" friction="1.0"/>
    </joint>

    <!-- Right lower leg -->
    <link name="right_lower_leg">
        <inertial>
            <origin xyz="0 0 -0.2" rpy="0 0 0"/>
            <mass value="3.0"/>
            <inertia ixx="0.1" ixy="0" ixz="0" iyy="0.1" iyz="0" izz="0.1"/>
        </inertial>
        <visual>
            <origin xyz="0 0 -0.2" rpy="0 0 0"/>
            <geometry>
                <box size="0.1 0.1 0.4"/>
            </geometry>
            <material name="green">
                <color rgba="0 1 0 1"/>
            </material>
        </visual>
        <collision>
            <origin xyz="0 0 -0.2" rpy="0 0 0"/>
            <geometry>
                <box size="0.06 0.06 0.36"/>
            </geometry>
        </collision>
    </link>

    <!-- Right foot with wider base and increased friction -->
    <joint name="right_ankle" type="fixed">
        <parent link="right_lower_leg"/>
        <child link="right_foot"/>
        <origin xyz="0 0 -0.4" rpy="0 0 0"/>
    </joint>

    <link name="right_foot">
        <inertial>
            <origin xyz="0 0 -0.025" rpy="0 0 0"/>
            <mass value="2.0"/>
            <inertia ixx="0.01" ixy="0" ixz="0" iyy="0.01" iyz="0" izz="0.01"/>
        </inertial>
        <visual>
            <origin xyz="0 0 -0.025" rpy="0 0 0"/>
            <geometry>
                <box size="0.2 0.2 0.05"/>
            </geometry>
            <material name="yellow">
                <color rgba="1 1 0 1"/>
            </material>
        </visual>
        <collision>
            <origin xyz="0 0 -0.025" rpy="0 0 0"/>
            <geometry>
                <box size="0.2 0.2 0.05"/>
            </geometry>
        </collision>
        <contact>
            <lateral_friction value="2.0"/>
            <rolling_friction value="0.2"/>
            <spinning_friction value="0.2"/>
            <restitution value="0.05"/>
        </contact>
    </link>
</robot>
